Workbook

Sheet Tickers
A1: Census M3 Table 2 - Industry별 FRED 티커
A2: Table 2: Value of Manufacturers' New Orders for Industry Groups (M3 Full Report). SA = Seasonally Adjusted, NSA = Not Seasonally Adjusted.
A4: Industry | B4: Level | C4: FRED Ticker (SA) | D4: FRED Ticker (NSA) | E4: FRED Title | F4: Units | G4: Latest Month | H4: Latest Value (SA) | I4: FRED Last Updated | J4: FRED URL (SA)
A5: All manufacturing industries | B5: 0 | C5: AMTMNO | D5: UMTMNO | E5: Manufacturers' New Orders: Total Manufacturing | F5: Millions of Dollars | G5: 2026-08 | H5: 663491 | I5: 2026-10-02 09:06:32-05 | J5: https://fred.stlouisfed.org/series/AMTMNO
A6: Excluding transportation | B6: 1 | C6: AMXTNO | D6: UMXTNO | E6: Manufacturers' New Orders: Manufacturing Excluding Transportation | F6: Millions of Dollars | G6: 2026-08 | H6: 549397 | I6: 2026-10-02 09:07:02-05 | J6: https://fred.stlouisfed.org/series/AMXTNO
A7: Excluding defense | B7: 1 | C7: AMXDNO | D7: UMXDNO | E7: Manufacturers' New Orders: Manufacturing Excluding Defense | F7: Millions of Dollars | G7: 2026-08 | H7: 638252 | I7: 2026-10-02 09:07:00-05 | J7: https://fred.stlouisfed.org/series/AMXDNO
A8: With unfilled orders | B8: 1 | C8: AMTUNO | D8: UMTUNO | E8: Manufacturers' New Orders: Manufacturing with Unfilled Orders | F8: Millions of Dollars | G8: 2026-09 | H8: 250863 | I8: 2026-10-27 07:33:33-05 | J8: https://fred.stlouisfed.org/series/AMTUNO
A9: Durable goods industries | B9: 0 | C9: DGORDER | D9: UMDMNO | E9: Manufacturers' New Orders: Durable Goods | F9: Millions of Dollars | G9: 2026-09 | H9: 345371 | I9: 2026-10-27 07:33:50-05 | J9: https://fred.stlouisfed.org/series/DGORDER
A10: Primary metals | B10: 1 | C10: A31SNO | D10: U31SNO | E10: Manufacturers' New Orders: Primary Metals | F10: Millions of Dollars | G10: 2026-09 | H10: 33010 | I10: 2026-10-27 07:33:25-05 | J10: https://fred.stlouisfed.org/series/A31SNO
A11: Iron and steel mills | B11: 2 | C11: A31ANO | D11: U31ANO | E11: Manufacturers' New Orders: Iron and Steel Mills and Ferroalloy and Steel Product Manufacturing | F11: Millions of Dollars | G11: 2026-08 | H11: 17466 | I11: 2026-10-02 09:06:35-05 | J11: https://fred.stlouisfed.org/series/A31ANO
A12: Aluminum and nonferrous metals | B12: 2 | C12: AANMNO | D12: UANMNO | E12: Manufacturers' New Orders: Aluminum and Nonferrous Metal Products | F12: Millions of Dollars | G12: 2026-08 | H12: 12861 | I12: 2026-10-02 09:06:46-05 | J12: https://fred.stlouisfed.org/series/AANMNO
A13: Ferrous metal foundries | B13: 2 | C13: A31CNO | D13: U31CNO | E13: Manufacturers' New Orders: Ferrous Metal Foundries | F13: Millions of Dollars | G13: 2026-08 | H13: 2277 | I13: 2026-10-02 09:06:39-05 | J13: https://fred.stlouisfed.org/series/A31CNO
A14: Fabricated metal products | B14: 1 | C14: A32SNO | D14: U32SNO | E14: Manufacturers' New Orders: Fabricated Metal Products | F14: Millions of Dollars | G14: 2026-09 | H14: 45159 | I14: 2026-10-27 07:33:28-05 | J14: https://fred.stlouisfed.org/series/A32SNO
A15: Machinery | B15: 1 | C15: A33SNO | D15: U33SNO | E15: Manufacturers' New Orders: Machinery | F15: Millions of Dollars | G15: 2026-09 | H15: 45977 | I15: 2026-10-27 07:33:29-05 | J15: https://fred.stlouisfed.org/series/A33SNO
A16: Construction machinery | B16: 2 | C16: A33CNO | D16: U33CNO | E16: Manufacturers' New Orders: Construction Machinery Manufacturing | F16: Millions of Dollars | G16: 2026-08 | H16: 5017 | I16: 2026-10-02 09:06:05-05 | J16: https://fred.stlouisfed.org/series/A33CNO
... A42: Nondurable goods industries | B42: 0 | C42: AMNMNO | D42: UMNMNO | E42: Manufacturers' New Orders: Nondurable Goods | F42: Millions of Dollars | G42: 2026-08 | H42: 325033 | I42: 2026-10-02 09:06:16-05 | J42: https://fred.stlouisfed.org/series/AMNMNO

Sheet 변동률
A1: Value of Manufacturers' New Orders for Industry Groups - Seasonally Adjusted, Monthly Percent Change
A2: 기준 선택 (MoM / YoY) ▶ | B2: MoM | C2: =IF($B$2="YoY","전년 동월 대비 변동률 (%)","전월 대비 변동률 (%)") -> 전월 대비 변동률 (%)
A3: Source: FRED (U.S. Census Bureau M3 Survey) via fred DB. 원계열은 Level_SA 시트. Computers and electronic products 등은 Census 기준대로 반도체 제외.
A4: Industry | B4: Ticker (SA) | C4: 2026-09 | D4: 2026-08 | E4: 2026-07 | F4: 2026-06 | G4: 2026-05 | H4: 2026-04 | I4: 2026-03 | J4: 2026-02 | K4: 2026-01 | L4: 2025-12 | M4: 2025-11 | N4: 2025-10 | O4: 2025-09 | P4: 2025-08 | Q4: 2025-07 | R4: 2025-06 | S4: 2025-05 | T4: 2025-04 | U4: 2025-03 | V4: 2025-02 | W4: 2025-01 | X4: 2024-12 | Y4: 2024-11 | Z4: 2024-10 | AA4: 2024-09 | AB4: 2024-08 | AC4: 2024-07 | AD4: 2024-06 | AE4: 2024-05 | AF4: 2024-04 | AG4: 2024-03 | AH4: 2024-02 | AI4: 2024-01 | AJ4: 2023-12 | AK4: 2023-11 | AL4: 2023-10 | AM4: 2023-09 | AN4: 2023-08 | AO4: 2023-07 | AP4: 2023-06 | AQ4: 2023-05 | AR4: 2023-04 | AS4: 2023-03 | AT4: 2023-02 | AU4: 2023-01 | AV4: 2022-12 | AW4: 2022-11 | AX4: 2022-10 | AY4: 2022-09 | AZ4: 2022-08 | BA4: 2022-07 | BB4: 2022-06 | BC4: 2022-05 | BD4: 2022-04 | BE4: 2022-03 | BF4: 2022-02 | BG4: 2022-01 | BH4: 2021-12 | BI4: 2021-11 | BJ4: 2021-10 | BK4: 2021-09 | BL4: 2021-08 | BM4: 2021-07 | BN4: 2021-06 | BO4: 2021-05 | BP4: 2021-04 | BQ4: 2021-03 | BR4: 2021-02 | BS4: 2021-01 | BT4: 2020-12 | BU4: 2020-11 | BV4: 2020-10 | BW4: 2020-09 | BX4: 2020-08 | BY4: 2020-07 | BZ4: 2020-06 | CA4: 2020-05 | CB4: 2020-04 | CC4: 2020-03 | CD4: 2020-02 | CE4: 2020-01 | CF4: 2019-12 | CG4: 2019-11 | CH4: 2019-10 | CI4: 2019-09 | CJ4: 2019-08 | CK4: 2019-07 | CL4: 2019-06 | CM4: 2019-05 | CN4: 2019-04 | CO4: 2019-03 | CP4: 2019-02 | CQ4: 2019-01 | CR4: 2018-12 | CS4: 2018-11 | CT4: 2018-10 | CU4: 2018-09 | CV4: 2018-08 | CW4: 2018-07 | CX4: 2018-06 | CY4: 2018-05 | CZ4: 2018-04 | DA4: 2018-03 | DB4: 2018-02 | DC4: 2018-01 | DD4: 2017-12 | DE4: 2017-11 | DF4: 2017-10 | DG4: 2017-09 | DH4: 2017-08 | DI4: 2017-07 | DJ4: 2017-06 | DK4: 2017-05 | DL4: 2017-04 | DM4: 2017-03 | DN4: 2017-02 | DO4: 2017-01 | DP4: 2016-12 | DQ4: 2016-11 | DR4: 2016-10 | DS4: 2016-09 | DT4: 2016-08 | DU4: 2016-07 | DV4: 2016-06 | DW4: 2016-05 | DX4: 2016-04 | DY4: 2016-03 | DZ4: 2016-02 | EA4: 2016-01 | EB4: 2015-12 | EC4: 2015-11 | ED4: 2015-10 | EE4: 2015-09 | EF4: 2015-08 | EG4: 2015-07 | EH4: 2015-06 | EI4: 2015-05 | EJ4: 2015-04 | EK4: 2015-03 | EL4: 2015-02 | EM4: 2015-01 | EN4: 2014-12 | EO4: 2014-11 | EP4: 2014-10 | EQ4: 2014-09 | ER4: 2014-08 | ES4: 2014-07 | ET4: 2014-06 | EU4: 2014-05 | EV4: 2014-04 | EW4: 2014-03 | EX4: 2014-02 | EY4: 2014-01 | EZ4: 2013-12 | FA4: 2013-11 | FB4: 2013-10 | FC4: 2013-09 | FD4: 2013-08 | FE4: 2013-07 | FF4: 2013-06 | FG4: 2013-05 | FH4: 2013-04 | FI4: 2013-03 | FJ4: 2013-02 | FK4: 2013-01 | FL4: 2012-12 | FM4: 2012-11 | FN4: 2012-10 | FO4: 2012-09 | FP4: 2012-08 | FQ4: 2012-07 | FR4: 2012-06 | FS4: 2012-05 | FT4: 2012-04 | FU4: 2012-03 | FV4: 2012-02 | FW4: 2012-01 | FX4: 2011-12 | FY4: 2011-11 | FZ4: 2011-10 | GA4: 2011-09 | GB4: 2011-08 | GC4: 2011-07 | GD4: 2011-06 | GE4: 2011-05 | GF4: 2011-04 | GG4: 2011-03 | GH4: 2011-02 | GI4: 2011-01 | GJ4: 2010-12 | GK4: 2010-11 | GL4: 2010-10 | GM4: 2010-09 | GN4: 2010-08 | GO4: 2010-07 | GP4: 2010-06 | GQ4: 2010-05 | GR4: 2010-04 | GS4: 2010-03 | GT4: 2010-02 | GU4: 2010-01 | GV4: 2009-12 | GW4: 2009-11 | GX4: 2009-10 | GY4: 2009-09 | GZ4: 2009-08 | HA4: 2009-07 | HB4: 2009-06 | HC4: 2009-05 | HD4: 2009-04 | HE4: 2009-03 | HF4: 2009-02 | HG4: 2009-01 | HH4: 2008-12 | HI4: 2008-11 | HJ4: 2008-10 | HK4: 2008-09 | HL4: 2008-08 | HM4: 2008-07 | HN4: 2008-06 | HO4: 2008-05 | HP4: 2008-04 | HQ4: 2008-03 | HR4: 2008-02 | HS4: 2008-01 | HT4: 2007-12 | HU4: 2007-11 | HV4: 2007-10 | HW4: 2007-09 | HX4: 2007-08 | HY4: 2007-07 | HZ4: 2007-06 | IA4: 2007-05 | IB4: 2007-04 | IC4: 2007-03 | ID4: 2007-02 | IE4: 2007-01 | IF4: 2006-12 | IG4: 2006-11 | IH4: 2006-10 | II4: 2006-09 | IJ4: 2006-08 | IK4: 2006-07 | IL4: 2006-06 | IM4: 2006-05 | IN4: 2006-04 | IO4: 2006-03 | IP4: 2006-02 | IQ4: 2006-01 | IR4: 2005-12 | IS4: 2005-11 | IT4: 2005-10 | IU4: 2005-09 | IV4: 2005-08 | IW4: 2005-07 | IX4: 2005-06 | IY4: 2005-05 | IZ4: 2005-04 | JA4: 2005-03 | JB4: 2005-02 | JC4: 2005-01 | JD4: 2004-12 | JE4: 2004-11 | JF4: 2004-10 | JG4: 2004-09 | JH4: 2004-08 | JI4: 2004-07 | JJ4: 2004-06 | JK4: 2004-05 | JL4: 2004-04 | JM4: 2004-03 | JN4: 2004-02 | JO4: 2004-01 | JP4: 2003-12 | JQ4: 2003-11 | JR4: 2003-10 | JS4: 2003-09 | JT4: 2003-08 | JU4: 2003-07 | JV4: 2003-06 | JW4: 2003-05 | JX4: 2003-04 | JY4: 2003-03 | JZ4: 2003-02 | KA4: 2003-01 | KB4: 2002-12 | KC4: 2002-11 | KD4: 2002-10 | KE4: 2002-09 | KF4: 2002-08 | KG4: 2002-07 | KH4: 2002-06 | KI4: 2002-05 | KJ4: 2002-04 | KK4: 2002-03 | KL4: 2002-02 | KM4: 2002-01 | KN4: 2001-12 | KO4: 2001-11 | KP4: 2001-10 | KQ4: 2001-09 | KR4: 2001-08 | KS4: 2001-07 | KT4: 2001-06 | KU4: 2001-05 | KV4: 2001-04 | KW4: 2001-03 | KX4: 2001-02 | KY4: 2001-01 | KZ4: 2000-12 | LA4: 2000-11 | LB4: 2000-10 | LC4: 2000-09 | LD4: 2000-08 | LE4: 2000-07 | LF4: 2000-06 | LG4: 2000-05 | LH4: 2000-04 | LI4: 2000-03 | LJ4: 2000-02 | LK4: 2000-01 | LL4: 1999-12 | LM4: 1999-11 | LN4: 1999-10 | LO4: 1999-09 | LP4: 1999-08 | LQ4: 1999-07 | LR4: 1999-06 | LS4: 1999-05 | LT4: 1999-04 | LU4: 1999-03 | LV4: 1999-02 | LW4: 1999-01 | LX4: 1998-12 | LY4: 1998-11 | LZ4: 1998-10 | MA4: 1998-09 | MB4: 1998-08 | MC4: 1998-07 | MD4: 1998-06 | ME4: 1998-05 | MF4: 1998-04 | MG4: 1998-03 | MH4: 1998-02 | MI4: 1998-01 | MJ4: 1997-12 | MK4: 1997-11 | ML4: 1997-10 | MM4: 1997-09 | MN4: 1997-08 | MO4: 1997-07 | MP4: 1997-06 | MQ4: 1997-05 | MR4: 1997-04 | MS4: 1997-03 | MT4: 1997-02 | MU4: 1997-01 | MV4: 1996-12 | MW4: 1996-11 | MX4: 1996-10 | MY4: 1996-09 | MZ4: 1996-08 | NA4: 1996-07 | NB4: 1996-06 | NC4: 1996-05 | ND4: 1996-04 | NE4: 1996-03 | NF4: 1996-02 | NG4: 1996-01 | NH4: 1995-12 | NI4: 1995-11 | NJ4: 1995-10 | NK4: 1995-09 | NL4: 1995-08 | NM4: 1995-07 | NN4: 1995-06 | NO4: 1995-05 | NP4: 1995-04 | NQ4: 1995-03 | NR4: 1995-02 | NS4: 1995-01 | NT4: 1994-12 | NU4: 1994-11 | NV4: 1994-10 | NW4: 1994-09 | NX4: 1994-08 | NY4: 1994-07 | NZ4: 1994-06 | OA4: 1994-05 | OB4: 1994-04 | OC4: 1994-03 | OD4: 1994-02 | OE4: 1994-01 | OF4: 1993-12 | OG4: 1993-11 | OH4: 1993-10 | OI4: 1993-09 | OJ4: 1993-08 | OK4: 1993-07 | OL4: 1993-06 | OM4: 1993-05 | ON4: 1993-04 | OO4: 1993-03 | OP4: 1993-02 | OQ4: 1993-01 | OR4: 1992-12 | OS4: 1992-11 | OT4: 1992-10 | OU4: 1992-09 | OV4: 1992-08 | OW4: 1992-07 | OX4: 1992-06 | OY4: 1992-05 | OZ4: 1992-04 | PA4: 1992-03 | PB4: 1992-02 | PC4: 1992-01
A5: All manufacturing industries | B5: AMTMNO | C5: =IF($B$2="YoY",IF(OR(Level_SA!C5="",Level_SA!O5="",Level_SA!O5=0),"",Level_SA!C5/Level_SA!O5-1),IF(OR(Level_SA!C5="",Level_SA!D5="",Level_SA!D5=0),"",Level_SA!C5/Level_SA!D5-1)) | D5: =IF($B$2="YoY",IF(OR(Level_SA!D5="",Level_SA!P5="",Level_SA!P5=0),"",Level_SA!D5/Level_SA!P5-1),IF(OR(Level_SA!D5="",Level_SA!E5="",Level_SA!E5=0),"",Level_SA!D5/Level_SA!E5-1)) -> 0.00098666791 | E5: =IF($B$2="YoY",IF(OR(Level_SA!E5="",Level_SA!Q5="",Level_SA!Q5=0),"",Level_SA!E5/Level_SA!Q5-1),IF(OR(Level_SA!E5="",Level_SA!F5="",Level_SA!F5=0),"",Level_SA!E5/Level_SA!F5-1)) -> 0.0076726615 | F5: =IF($B$2="YoY",IF(OR(Level_SA!F5="",Level_SA!R5="",Level_SA!R5=0),"",Level_SA!F5/Level_SA!R5-1),IF(OR(Level_SA!F5="",Level_SA!G5="",Level_SA!G5=0),"",Level_SA!F5/Level_SA!G5-1)) -> -0.0015876485 | G5: =IF($B$2="YoY",IF(OR(Level_SA!G5="",Level_SA!S5="",Level_SA!S5=0),"",Level_SA!G5/Level_SA!S5-1),IF(OR(Level_SA!G5="",Level_SA!H5="",Level_SA!H5=0),"",Level_SA!G5/Level_SA!H5-1)) -> -0.01060077 | H5: =IF($B$2="YoY",IF(OR(Level_SA!H5="",Level_SA!T5="",Level_SA!T5=0),"",Level_SA!H5/Level_SA!T5-1),IF(OR(Level_SA!H5="",Level_SA!I5="",Level_SA!I5=0),"",Level_SA!H5/Level_SA!I5-1)) -> 0.052548803 | I5: =IF($B$2="YoY",IF(OR(Level_SA!I5="",Level_SA!U5="",Level_SA!U5=0),"",Level_SA!I5/Level_SA!U5-1),IF(OR(Level_SA!I5="",Level_SA!J5="",Level_SA!J5=0),"",Level_SA!I5/Level_SA!J5-1)) -> 0.018261592 | J5: =IF($B$2="YoY",IF(OR(Level_SA!J5="",Level_SA!V5="",Level_SA!V5=0),"",Level_SA!J5/Level_SA!V5-1),IF(OR(Level_SA!J5="",Level_SA!K5="",Level_SA!K5=0),"",Level_SA!J5/Level_SA!K5-1)) -> 0.0031516811 | ... OQ5: =IF($B$2="YoY",IF(OR(Level_SA!OQ5="",Level_SA!PC5="",Level_SA!PC5=0),"",Level_SA!OQ5/Level_SA!PC5-1),IF(OR(Level_SA!OQ5="",Level_SA!OR5="",Level_SA!OR5=0),"",Level_SA!OQ5/Level_SA!OR5-1)) -> -0.017401596 | OR5: =IF($B$2="YoY","",IF(OR(Level_SA!OR5="",Level_SA!OS5="",Level_SA!OS5=0),"",Level_SA!OR5/Level_SA!OS5-1)) -> 0.016176556 | OS5: =IF($B$2="YoY","",IF(OR(Level_SA!OS5="",Level_SA!OT5="",Level_SA!OT5=0),"",Level_SA!OS5/Level_SA!OT5-1)) -> -0.010366429 | OT5: =IF($B$2="YoY","",IF(OR(Level_SA!OT5="",Level_SA!OU5="",Level_SA!OU5=0),"",Level_SA!OT5/Level_SA!OU5-1)) -> 0.015691147 | OU5: =IF($B$2="YoY","",IF(OR(Level_SA!OU5="",Level_SA!OV5="",Level_SA!OV5=0),"",Level_SA!OU5/Level_SA!OV5-1)) -> 0.014509852 | OV5: =IF($B$2="YoY","",IF(OR(Level_SA!OV5="",Level_SA!OW5="",Level_SA!OW5=0),"",Level_SA!OV5/Level_SA!OW5-1)) -> -0.012472287 | OW5: =IF($B$2="YoY","",IF(OR(Level_SA!OW5="",Level_SA!OX5="",Level_SA!OX5=0),"",Level_SA!OW5/Level_SA!OX5-1)) -> -0.0085223967 | OX5: =IF($B$2="YoY","",IF(OR(Level_SA!OX5="",Level_SA!OY5="",Level_SA!OY5=0),"",Level_SA!OX5/Level_SA!OY5-1)) -> -0.0051918848 | OY5: =IF($B$2="YoY","",IF(OR(Level_SA!OY5="",Level_SA!OZ5="",Level_SA!OZ5=0),"",Level_SA!OY5/Level_SA!OZ5-1)) -> 0.015715467 | ... PB5: =IF($B$2="YoY","",IF(OR(Level_SA!PB5="",Level_SA!PC5="",Level_SA!PC5=0),"",Level_SA!PB5/Level_SA!PC5-1)) | PC5: =IF($B$2="YoY","","")
A6: Excluding transportation | B6: AMXTNO | C6: =IF($B$2="YoY",IF(OR(Level_SA!C6="",Level_SA!O6="",Level_SA!O6=0),"",Level_SA!C6/Level_SA!O6-1),IF(OR(Level_SA!C6="",Level_SA!D6="",Level_SA!D6=0),"",Level_SA!C6/Level_SA!D6-1)) | D6: =IF($B$2="YoY",IF(OR(Level_SA!D6="",Level_SA!P6="",Level_SA!P6=0),"",Level_SA!D6/Level_SA!P6-1),IF(OR(Level_SA!D6="",Level_SA!E6="",Level_SA!E6=0),"",Level_SA!D6/Level_SA!E6-1)) -> 0.0026407519 | E6: =IF($B$2="YoY",IF(OR(Level_SA!E6="",Level_SA!Q6="",Level_SA!Q6=0),"",Level_SA!E6/Level_SA!Q6-1),IF(OR(Level_SA!E6="",Level_SA!F6="",Level_SA!F6=0),"",Level_SA!E6/Level_SA!F6-1)) -> 0.0068223954 | F6: =IF($B$2="YoY",IF(OR(Level_SA!F6="",Level_SA!R6="",Level_SA!R6=0),"",Level_SA!F6/Level_SA!R6-1),IF(OR(Level_SA!F6="",Level_SA!G6="",Level_SA!G6=0),"",Level_SA!F6/Level_SA!G6-1)) -> -0.00089219658 | G6: =IF($B$2="YoY",IF(OR(Level_SA!G6="",Level_SA!S6="",Level_SA!S6=0),"",Level_SA!G6/Level_SA!S6-1),IF(OR(Level_SA!G6="",Level_SA!H6="",Level_SA!H6=0),"",Level_SA!G6/Level_SA!H6-1)) -> 0.020132104 | H6: =IF($B$2="YoY",IF(OR(Level_SA!H6="",Level_SA!T6="",Level_SA!T6=0),"",Level_SA!H6/Level_SA!T6-1),IF(OR(Level_SA!H6="",Level_SA!I6="",Level_SA!I6=0),"",Level_SA!H6/Level_SA!I6-1)) -> 0.017322022 | I6: =IF($B$2="YoY",IF(OR(Level_SA!I6="",Level_SA!U6="",Level_SA!U6=0),"",Level_SA!I6/Level_SA!U6-1),IF(OR(Level_SA!I6="",Level_SA!J6="",Level_SA!J6=0),"",Level_SA!I6/Level_SA!J6-1)) -> 0.018393445 | J6: =IF($B$2="YoY",IF(OR(Level_SA!J6="",Level_SA!V6="",Level_SA!V6=0),"",Level_SA!J6/Level_SA!V6-1),IF(OR(Level_SA!J6="",Level_SA!K6="",Level_SA!K6=0),"",Level_SA!J6/Level_SA!K6-1)) -> 0.016339489 | ... OQ6: =IF($B$2="YoY",IF(OR(Level_SA!OQ6="",Level_SA!PC6="",Level_SA!PC6=0),"",Level_SA!OQ6/Level_SA!PC6-1),IF(OR(Level_SA!OQ6="",Level_SA!OR6="",Level_SA!OR6=0),"",Level_SA!OQ6/Level_SA!OR6-1)) -> -0.00043446709 | OR6: =IF($B$2="YoY","",IF(OR(Level_SA!OR6="",Level_SA!OS6="",Level_SA!OS6=0),"",Level_SA!OR6/Level_SA!OS6-1)) -> 0.0098501029 | OS6: =IF($B$2="YoY","",IF(OR(Level_SA!OS6="",Level_SA!OT6="",Level_SA!OT6=0),"",Level_SA!OS6/Level_SA!OT6-1)) -> 0.024368441 | OT6: =IF($B$2="YoY","",IF(OR(Level_SA!OT6="",Level_SA!OU6="",Level_SA!OU6=0),"",Level_SA!OT6/Level_SA!OU6-1)) -> -0.021963849 | OU6: =IF($B$2="YoY","",IF(OR(Level_SA!OU6="",Level_SA!OV6="",Level_SA!OV6=0),"",Level_SA!OU6/Level_SA!OV6-1)) -> 0.021226427 | OV6: =IF($B$2="YoY","",IF(OR(Level_SA!OV6="",Level_SA!OW6="",Level_SA!OW6=0),"",Level_SA!OV6/Level_SA!OW6-1)) -> -0.0050405898 | OW6: =IF($B$2="YoY","",IF(OR(Level_SA!OW6="",Level_SA!OX6="",Level_SA!OX6=0),"",Level_SA!OW6/Level_SA!OX6-1)) -> -0.011157757 | OX6: =IF($B$2="YoY","",IF(OR(Level_SA!OX6="",Level_SA!OY6="",Level_SA!OY6=0),"",Level_SA!OX6/Level_SA!OY6-1)) -> 0.0078802939 | OY6: =IF($B$2="YoY","",IF(OR(Level_SA!OY6="",Level_SA!OZ6="",Level_SA!OZ6=0),"",Level_SA!OY6/Level_SA!OZ6-1)) -> 0.020603374 | ... PB6: =IF($B$2="YoY","",IF(OR(Level_SA!PB6="",Level_SA!PC6="",Level_SA!PC6=0),"",Level_SA!PB6/Level_SA!PC6-1)) | PC6: =IF($B$2="YoY","","")
A7: Excluding defense | B7: AMXDNO | C7: =IF($B$2="YoY",IF(OR(Level_SA!C7="",Level_SA!O7="",Level_SA!O7=0),"",Level_SA!C7/Level_SA!O7-1),IF(OR(Level_SA!C7="",Level_SA!D7="",Level_SA!D7=0),"",Level_SA!C7/Level_SA!D7-1)) | D7: =IF($B$2="YoY",IF(OR(Level_SA!D7="",Level_SA!P7="",Level_SA!P7=0),"",Level_SA!D7/Level_SA!P7-1),IF(OR(Level_SA!D7="",Level_SA!E7="",Level_SA!E7=0),"",Level_SA!D7/Level_SA!E7-1)) -> 0.0013665296 | E7: =IF($B$2="YoY",IF(OR(Level_SA!E7="",Level_SA!Q7="",Level_SA!Q7=0),"",Level_SA!E7/Level_SA!Q7-1),IF(OR(Level_SA!E7="",Level_SA!F7="",Level_SA!F7=0),"",Level_SA!E7/Level_SA!F7-1)) -> 0.010355902 | F7: =IF($B$2="YoY",IF(OR(Level_SA!F7="",Level_SA!R7="",Level_SA!R7=0),"",Level_SA!F7/Level_SA!R7-1),IF(OR(Level_SA!F7="",Level_SA!G7="",Level_SA!G7=0),"",Level_SA!F7/Level_SA!G7-1)) -> -0.0029933211 | G7: =IF($B$2="YoY",IF(OR(Level_SA!G7="",Level_SA!S7="",Level_SA!S7=0),"",Level_SA!G7/Level_SA!S7-1),IF(OR(Level_SA!G7="",Level_SA!H7="",Level_SA!H7=0),"",Level_SA!G7/Level_SA!H7-1)) -> -0.010685204 | H7: =IF($B$2="YoY",IF(OR(Level_SA!H7="",Level_SA!T7="",Level_SA!T7=0),"",Level_SA!H7/Level_SA!T7-1),IF(OR(Level_SA!H7="",Level_SA!I7="",Level_SA!I7=0),"",Level_SA!H7/Level_SA!I7-1)) -> 0.051073299 | I7: =IF($B$2="YoY",IF(OR(Level_SA!I7="",Level_SA!U7="",Level_SA!U7=0),"",Level_SA!I7/Level_SA!U7-1),IF(OR(Level_SA!I7="",Level_SA!J7="",Level_SA!J7=0),"",Level_SA!I7/Level_SA!J7-1)) -> 0.010443218 | J7: =IF($B$2="YoY",IF(OR(Level_SA!J7="",Level_SA!V7="",Level_SA!V7=0),"",Level_SA!J7/Level_SA!V7-1),IF(OR(Level_SA!J7="",Level_SA!K7="",Level_SA!K7=0),"",Level_SA!J7/Level_SA!K7-1)) -> 0.0033605913 | ... OQ7: =IF($B$2="YoY",IF(OR(Level_SA!OQ7="",Level_SA!PC7="",Level_SA!PC7=0),"",Level_SA!OQ7/Level_SA!PC7-1),IF(OR(Level_SA!OQ7="",Level_SA!OR7="",Level_SA!OR7=0),"",Level_SA!OQ7/Level_SA!OR7-1)) -> -0.0080281601 | OR7: =IF($B$2="YoY","",IF(OR(Level_SA!OR7="",Level_SA!OS7="",Level_SA!OS7=0),"",Level_SA!OR7/Level_SA!OS7-1)) -> 0.01623511 | OS7: =IF($B$2="YoY","",IF(OR(Level_SA!OS7="",Level_SA!OT7="",Level_SA!OT7=0),"",Level_SA!OS7/Level_SA!OT7-1)) -> 0.0038505135 | OT7: =IF($B$2="YoY","",IF(OR(Level_SA!OT7="",Level_SA!OU7="",Level_SA!OU7=0),"",Level_SA!OT7/Level_SA!OU7-1)) -> -0.0052719237 | OU7: =IF($B$2="YoY","",IF(OR(Level_SA!OU7="",Level_SA!OV7="",Level_SA!OV7=0),"",Level_SA!OU7/Level_SA!OV7-1)) -> 0.011302804 | OV7: =IF($B$2="YoY","",IF(OR(Level_SA!OV7="",Level_SA!OW7="",Level_SA!OW7=0),"",Level_SA!OV7/Level_SA!OW7-1)) -> -0.012727304 | OW7: =IF($B$2="YoY","",IF(OR(Level_SA!OW7="",Level_SA!OX7="",Level_SA!OX7=0),"",Level_SA!OW7/Level_SA!OX7-1)) -> -0.0041762229 | OX7: =IF($B$2="YoY","",IF(OR(Level_SA!OX7="",Level_SA!OY7="",Level_SA!OY7=0),"",Level_SA!OX7/Level_SA!OY7-1)) -> 2.1395042e-05 | OY7: =IF($B$2="YoY","",IF(OR(Level_SA!OY7="",Level_SA!OZ7="",Level_SA!OZ7=0),"",Level_SA!OY7/Level_SA!OZ7-1)) -> 0.017418523 | ... PB7: =IF($B$2="YoY","",IF(OR(Level_SA!PB7="",Level_SA!PC7="",Level_SA!PC7=0),"",Level_SA!PB7/Level_SA!PC7-1)) | PC7: =IF($B$2="YoY","","")
A8: With unfilled orders | B8: AMTUNO | C8: =IF($B$2="YoY",IF(OR(Level_SA!C8="",Level_SA!O8="",Level_SA!O8=0),"",Level_SA!C8/Level_SA!O8-1),IF(OR(Level_SA!C8="",Level_SA!D8="",Level_SA!D8=0),"",Level_SA!C8/Level_SA!D8-1)) -> 0.024014205 | D8: =IF($B$2="YoY",IF(OR(Level_SA!D8="",Level_SA!P8="",Level_SA!P8=0),"",Level_SA!D8/Level_SA!P8-1),IF(OR(Level_SA!D8="",Level_SA!E8="",Level_SA!E8=0),"",Level_SA!D8/Level_SA!E8-1)) -> 0.00369554 | E8: =IF($B$2="YoY",IF(OR(Level_SA!E8="",Level_SA!Q8="",Level_SA!Q8=0),"",Level_SA!E8/Level_SA!Q8-1),IF(OR(Level_SA!E8="",Level_SA!F8="",Level_SA!F8=0),"",Level_SA!E8/Level_SA!F8-1)) -> 0.0091747671 | F8: =IF($B$2="YoY",IF(OR(Level_SA!F8="",Level_SA!R8="",Level_SA!R8=0),"",Level_SA!F8/Level_SA!R8-1),IF(OR(Level_SA!F8="",Level_SA!G8="",Level_SA!G8=0),"",Level_SA!F8/Level_SA!G8-1)) -> 0.0090870782 | G8: =IF($B$2="YoY",IF(OR(Level_SA!G8="",Level_SA!S8="",Level_SA!S8=0),"",Level_SA!G8/Level_SA!S8-1),IF(OR(Level_SA!G8="",Level_SA!H8="",Level_SA!H8=0),"",Level_SA!G8/Level_SA!H8-1)) -> -0.056667414 | H8: =IF($B$2="YoY",IF(OR(Level_SA!H8="",Level_SA!T8="",Level_SA!T8=0),"",Level_SA!H8/Level_SA!T8-1),IF(OR(Level_SA!H8="",Level_SA!I8="",Level_SA!I8=0),"",Level_SA!H8/Level_SA!I8-1)) -> 0.11840391 | I8: =IF($B$2="YoY",IF(OR(Level_SA!I8="",Level_SA!U8="",Level_SA!U8=0),"",Level_SA!I8/Level_SA!U8-1),IF(OR(Level_SA!I8="",Level_SA!J8="",Level_SA!J8=0),"",Level_SA!I8/Level_SA!J8-1)) -> 0.015025668 | J8: =IF($B$2="YoY",IF(OR(Level_SA!J8="",Level_SA!V8="",Level_SA!V8=0),"",Level_SA!J8/Level_SA!V8-1),IF(OR(Level_SA!J8="",Level_SA!K8="",Level_SA!K8=0),"",Level_SA!J8/Level_SA!K8-1)) -> -0.026425452 | ... OQ8: =IF($B$2="YoY",IF(OR(Level_SA!OQ8="",Level_SA!PC8="",Level_SA!PC8=0),"",Level_SA!OQ8/Level_SA!PC8-1),IF(OR(Level_SA!OQ8="",Level_SA!OR8="",Level_SA!OR8=0),"",Level_SA!OQ8/Level_SA!OR8-1)) -> -0.060592479 | OR8: =IF($B$2="YoY","",IF(OR(Level_SA!OR8="",Level_SA!OS8="",Level_SA!OS8=0),"",Level_SA!OR8/Level_SA!OS8-1)) -> 0.044137286 | OS8: =IF($B$2="YoY","",IF(OR(Level_SA!OS8="",Level_SA!OT8="",Level_SA!OT8=0),"",Level_SA!OS8/Level_SA!OT8-1)) -> -0.05844107 | OT8: =IF($B$2="YoY","",IF(OR(Level_SA!OT8="",Level_SA!OU8="",Level_SA!OU8=0),"",Level_SA!OT8/Level_SA!OU8-1)) -> 0.073648867 | OU8: =IF($B$2="YoY","",IF(OR(Level_SA!OU8="",Level_SA!OV8="",Level_SA!OV8=0),"",Level_SA!OU8/Level_SA!OV8-1)) -> 0.0078260364 | OV8: =IF($B$2="YoY","",IF(OR(Level_SA!OV8="",Level_SA!OW8="",Level_SA!OW8=0),"",Level_SA!OV8/Level_SA!OW8-1)) -> -0.015422134 | OW8: =IF($B$2="YoY","",IF(OR(Level_SA!OW8="",Level_SA!OX8="",Level_SA!OX8=0),"",Level_SA!OW8/Level_SA!OX8-1)) -> -0.014743539 | OX8: =IF($B$2="YoY","",IF(OR(Level_SA!OX8="",Level_SA!OY8="",Level_SA!OY8=0),"",Level_SA!OX8/Level_SA!OY8-1)) -> -0.027118086 | OY8: =IF($B$2="YoY","",IF(OR(Level_SA!OY8="",Level_SA!OZ8="",Level_SA!OZ8=0),"",Level_SA!OY8/Level_SA!OZ8-1)) -> 0.003468972 | ... PB8: =IF($B$2="YoY","",IF(OR(Level_SA!PB8="",Level_SA!PC8="",Level_SA!PC8=0),"",Level_SA!PB8/Level_SA!PC8-1)) | PC8: =IF($B$2="YoY","","")
A9: Durable goods industries | B9: DGORDER | C9: =IF($B$2="YoY",IF(OR(Level_SA!C9="",Level_SA!O9="",Level_SA!O9=0),"",Level_SA!C9/Level_SA!O9-1),IF(OR(Level_SA!C9="",Level_SA!D9="",Level_SA!D9=0),"",Level_SA!C9/Level_SA!D9-1)) -> 0.018442013 | D9: =IF($B$2="YoY",IF(OR(Level_SA!D9="",Level_SA!P9="",Level_SA!P9=0),"",Level_SA!D9/Level_SA!P9-1),IF(OR(Level_SA!D9="",Level_SA!E9="",Level_SA!E9=0),"",Level_SA!D9/Level_SA!E9-1)) -> 0.001231178 | E9: =IF($B$2="YoY",IF(OR(Level_SA!E9="",Level_SA!Q9="",Level_SA!Q9=0),"",Level_SA!E9/Level_SA!Q9-1),IF(OR(Level_SA!E9="",Level_SA!F9="",Level_SA!F9=0),"",Level_SA!E9/Level_SA!F9-1)) -> 0.0086991742 | F9: =IF($B$2="YoY",IF(OR(Level_SA!F9="",Level_SA!R9="",Level_SA!R9=0),"",Level_SA!F9/Level_SA!R9-1),IF(OR(Level_SA!F9="",Level_SA!G9="",Level_SA!G9=0),"",Level_SA!F9/Level_SA!G9-1)) -> 0.0058021459 | G9: =IF($B$2="YoY",IF(OR(Level_SA!G9="",Level_SA!S9="",Level_SA!S9=0),"",Level_SA!G9/Level_SA!S9-1),IF(OR(Level_SA!G9="",Level_SA!H9="",Level_SA!H9=0),"",Level_SA!G9/Level_SA!H9-1)) -> -0.040041177 | H9: =IF($B$2="YoY",IF(OR(Level_SA!H9="",Level_SA!T9="",Level_SA!T9=0),"",Level_SA!H9/Level_SA!T9-1),IF(OR(Level_SA!H9="",Level_SA!I9="",Level_SA!I9=0),"",Level_SA!H9/Level_SA!I9-1)) -> 0.085127229 | I9: =IF($B$2="YoY",IF(OR(Level_SA!I9="",Level_SA!U9="",Level_SA!U9=0),"",Level_SA!I9/Level_SA!U9-1),IF(OR(Level_SA!I9="",Level_SA!J9="",Level_SA!J9=0),"",Level_SA!I9/Level_SA!J9-1)) -> 0.013445782 | J9: =IF($B$2="YoY",IF(OR(Level_SA!J9="",Level_SA!V9="",Level_SA!V9=0),"",Level_SA!J9/Level_SA!V9-1),IF(OR(Level_SA!J9="",Level_SA!K9="",Level_SA!K9=0),"",Level_SA!J9/Level_SA!K9-1)) -> -0.011694664 | ... OQ9: =IF($B$2="YoY",IF(OR(Level_SA!OQ9="",Level_SA!PC9="",Level_SA!PC9=0),"",Level_SA!OQ9/Level_SA!PC9-1),IF(OR(Level_SA!OQ9="",Level_SA!OR9="",Level_SA!OR9=0),"",Level_SA!OQ9/Level_SA!OR9-1)) -> -0.03523953 | OR9: =IF($B$2="YoY","",IF(OR(Level_SA!OR9="",Level_SA!OS9="",Level_SA!OS9=0),"",Level_SA!OR9/Level_SA!OS9-1)) -> 0.030284211 | OS9: =IF($B$2="YoY","",IF(OR(Level_SA!OS9="",Level_SA!OT9="",Level_SA!OT9=0),"",Level_SA!OS9/Level_SA!OT9-1)) -> -0.039390229 | OT9: =IF($B$2="YoY","",IF(OR(Level_SA!OT9="",Level_SA!OU9="",Level_SA!OU9=0),"",Level_SA!OT9/Level_SA!OU9-1)) -> 0.055347069 | OU9: =IF($B$2="YoY","",IF(OR(Level_SA!OU9="",Level_SA!OV9="",Level_SA!OV9=0),"",Level_SA!OU9/Level_SA!OV9-1)) -> 0.0024914667 | OV9: =IF($B$2="YoY","",IF(OR(Level_SA!OV9="",Level_SA!OW9="",Level_SA!OW9=0),"",Level_SA!OV9/Level_SA!OW9-1)) -> -0.017774696 | OW9: =IF($B$2="YoY","",IF(OR(Level_SA!OW9="",Level_SA!OX9="",Level_SA!OX9=0),"",Level_SA!OW9/Level_SA!OX9-1)) -> -0.0019864207 | OX9: =IF($B$2="YoY","",IF(OR(Level_SA!OX9="",Level_SA!OY9="",Level_SA!OY9=0),"",Level_SA!OX9/Level_SA!OY9-1)) -> -0.023747834 | OY9: =IF($B$2="YoY","",IF(OR(Level_SA!OY9="",Level_SA!OZ9="",Level_SA!OZ9=0),"",Level_SA!OY9/Level_SA!OZ9-1)) -> 0.010862055 | ... PB9: =IF($B$2="YoY","",IF(OR(Level_SA!PB9="",Level_SA!PC9="",Level_SA!PC9=0),"",Level_SA!PB9/Level_SA!PC9-1)) | PC9: =IF($B$2="YoY","","")
A10: Primary metals | B10: A31SNO | C10: =IF($B$2="YoY",IF(OR(Level_SA!C10="",Level_SA!O10="",Level_SA!O10=0),"",Level_SA!C10/Level_SA!O10-1),IF(OR(Level_SA!C10="",Level_SA!D10="",Level_SA!D10=0),"",Level_SA!C10/Level_SA!D10-1)) -> 0.0051460065 | D10: =IF($B$2="YoY",IF(OR(Level_SA!D10="",Level_SA!P10="",Level_SA!P10=0),"",Level_SA!D10/Level_SA!P10-1),IF(OR(Level_SA!D10="",Level_SA!E10="",Level_SA!E10=0),"",Level_SA!D10/Level_SA!E10-1)) -> 0.019210477 | E10: =IF($B$2="YoY",IF(OR(Level_SA!E10="",Level_SA!Q10="",Level_SA!Q10=0),"",Level_SA!E10/Level_SA!Q10-1),IF(OR(Level_SA!E10="",Level_SA!F10="",Level_SA!F10=0),"",Level_SA!E10/Level_SA!F10-1)) -> 0.02136427 | F10: =IF($B$2="YoY",IF(OR(Level_SA!F10="",Level_SA!R10="",Level_SA!R10=0),"",Level_SA!F10/Level_SA!R10-1),IF(OR(Level_SA!F10="",Level_SA!G10="",Level_SA!G10=0),"",Level_SA!F10/Level_SA!G10-1)) -> 0.018663222 | G10: =IF($B$2="YoY",IF(OR(Level_SA!G10="",Level_SA!S10="",Level_SA!S10=0),"",Level_SA!G10/Level_SA!S10-1),IF(OR(Level_SA!G10="",Level_SA!H10="",Level_SA!H10=0),"",Level_SA!G10/Level_SA!H10-1)) -> 0.042585423 | H10: =IF($B$2="YoY",IF(OR(Level_SA!H10="",Level_SA!T10="",Level_SA!T10=0),"",Level_SA!H10/Level_SA!T10-1),IF(OR(Level_SA!H10="",Level_SA!I10="",Level_SA!I10=0),"",Level_SA!H10/Level_SA!I10-1)) -> 0.026895288 | I10: =IF($B$2="YoY",IF(OR(Level_SA!I10="",Level_SA!U10="",Level_SA!U10=0),"",Level_SA!I10/Level_SA!U10-1),IF(OR(Level_SA!I10="",Level_SA!J10="",Level_SA!J10=0),"",Level_SA!I10/Level_SA!J10-1)) -> 0.0081201645 | J10: =IF($B$2="YoY",IF(OR(Level_SA!J10="",Level_SA!V10="",Level_SA!V10=0),"",Level_SA!J10/Level_SA!V10-1),IF(OR(Level_SA!J10="",Level_SA!K10="",Level_SA!K10=0),"",Level_SA!J10/Level_SA!K10-1)) -> 0.024639337 | ... OQ10: =IF($B$2="YoY",IF(OR(Level_SA!OQ10="",Level_SA!PC10="",Level_SA!PC10=0),"",Level_SA!OQ10/Level_SA!PC10-1),IF(OR(Level_SA!OQ10="",Level_SA!OR10="",Level_SA!OR10=0),"",Level_SA!OQ10/Level_SA!OR10-1)) -> 0.027259008 | OR10: =IF($B$2="YoY","",IF(OR(Level_SA!OR10="",Level_SA!OS10="",Level_SA!OS10=0),"",Level_SA!OR10/Level_SA!OS10-1)) -> 0.04970297 | OS10: =IF($B$2="YoY","",IF(OR(Level_SA!OS10="",Level_SA!OT10="",Level_SA!OT10=0),"",Level_SA!OS10/Level_SA!OT10-1)) -> 0.02061439 | OT10: =IF($B$2="YoY","",IF(OR(Level_SA!OT10="",Level_SA!OU10="",Level_SA!OU10=0),"",Level_SA!OT10/Level_SA!OU10-1)) -> -0.001110326 | OU10: =IF($B$2="YoY","",IF(OR(Level_SA!OU10="",Level_SA!OV10="",Level_SA!OV10=0),"",Level_SA!OU10/Level_SA!OV10-1)) -> -0.080812767 | OV10: =IF($B$2="YoY","",IF(OR(Level_SA!OV10="",Level_SA!OW10="",Level_SA!OW10=0),"",Level_SA!OV10/Level_SA!OW10-1)) -> -0.0021294325 | OW10: =IF($B$2="YoY","",IF(OR(Level_SA!OW10="",Level_SA!OX10="",Level_SA!OX10=0),"",Level_SA!OW10/Level_SA!OX10-1)) -> -0.0019404916 | OX10: =IF($B$2="YoY","",IF(OR(Level_SA!OX10="",Level_SA!OY10="",Level_SA!OY10=0),"",Level_SA!OX10/Level_SA!OY10-1)) -> 0.0039892383 | OY10: =IF($B$2="YoY","",IF(OR(Level_SA!OY10="",Level_SA!OZ10="",Level_SA!OZ10=0),"",Level_SA!OY10/Level_SA!OZ10-1)) -> 0.031285878 | ... PB10: =IF($B$2="YoY","",IF(OR(Level_SA!PB10="",Level_SA!PC10="",Level_SA!PC10=0),"",Level_SA!PB10/Level_SA!PC10-1)) | PC10: =IF($B$2="YoY","","")
A11: Iron and steel mills | B11: A31ANO | C11: =IF($B$2="YoY",IF(OR(Level_SA!C11="",Level_SA!O11="",Level_SA!O11=0),"",Level_SA!C11/Level_SA!O11-1),IF(OR(Level_SA!C11="",Level_SA!D11="",Level_SA!D11=0),"",Level_SA!C11/Level_SA!D11-1)) | D11: =IF($B$2="YoY",IF(OR(Level_SA!D11="",Level_SA!P11="",Level_SA!P11=0),"",Level_SA!D11/Level_SA!P11-1),IF(OR(Level_SA!D11="",Level_SA!E11="",Level_SA!E11=0),"",Level_SA!D11/Level_SA!E11-1)) -> 0.0090704258 | E11: =IF($B$2="YoY",IF(OR(Level_SA!E11="",Level_SA!Q11="",Level_SA!Q11=0),"",Level_SA!E11/Level_SA!Q11-1),IF(OR(Level_SA!E11="",Level_SA!F11="",Level_SA!F11=0),"",Level_SA!E11/Level_SA!F11-1)) -> 0.030542986 | F11: =IF($B$2="YoY",IF(OR(Level_SA!F11="",Level_SA!R11="",Level_SA!R11=0),"",Level_SA!F11/Level_SA!R11-1),IF(OR(Level_SA!F11="",Level_SA!G11="",Level_SA!G11=0),"",Level_SA!F11/Level_SA!G11-1)) -> 0.027718289 | G11: =IF($B$2="YoY",IF(OR(Level_SA!G11="",Level_SA!S11="",Level_SA!S11=0),"",Level_SA!G11/Level_SA!S11-1),IF(OR(Level_SA!G11="",Level_SA!H11="",Level_SA!H11=0),"",Level_SA!G11/Level_SA!H11-1)) -> 0.041685257 | H11: =IF($B$2="YoY",IF(OR(Level_SA!H11="",Level_SA!T11="",Level_SA!T11=0),"",Level_SA!H11/Level_SA!T11-1),IF(OR(Level_SA!H11="",Level_SA!I11="",Level_SA!I11=0),"",Level_SA!H11/Level_SA!I11-1)) -> 0.017576858 | I11: =IF($B$2="YoY",IF(OR(Level_SA!I11="",Level_SA!U11="",Level_SA!U11=0),"",Level_SA!I11/Level_SA!U11-1),IF(OR(Level_SA!I11="",Level_SA!J11="",Level_SA!J11=0),"",Level_SA!I11/Level_SA!J11-1)) -> 0.029720163 | J11: =IF($B$2="YoY",IF(OR(Level_SA!J11="",Level_SA!V11="",Level_SA!V11=0),"",Level_SA!J11/Level_SA!V11-1),IF(OR(Level_SA!J11="",Level_SA!K11="",Level_SA!K11=0),"",Level_SA!J11/Level_SA!K11-1)) -> 0.024355203 | ... OQ11: =IF($B$2="YoY",IF(OR(Level_SA!OQ11="",Level_SA!PC11="",Level_SA!PC11=0),"",Level_SA!OQ11/Level_SA!PC11-1),IF(OR(Level_SA!OQ11="",Level_SA!OR11="",Level_SA!OR11=0),"",Level_SA!OQ11/Level_SA!OR11-1)) -> 0.022187622 | OR11: =IF($B$2="YoY","",IF(OR(Level_SA!OR11="",Level_SA!OS11="",Level_SA!OS11=0),"",Level_SA!OR11/Level_SA!OS11-1)) -> 0.16481523 | OS11: =IF($B$2="YoY","",IF(OR(Level_SA!OS11="",Level_SA!OT11="",Level_SA!OT11=0),"",Level_SA!OS11/Level_SA!OT11-1)) -> 0.019412988 | OT11: =IF($B$2="YoY","",IF(OR(Level_SA!OT11="",Level_SA!OU11="",Level_SA!OU11=0),"",Level_SA!OT11/Level_SA!OU11-1)) -> -0.039085054 | OU11: =IF($B$2="YoY","",IF(OR(Level_SA!OU11="",Level_SA!OV11="",Level_SA!OV11=0),"",Level_SA!OU11/Level_SA!OV11-1)) -> -0.051600674 | OV11: =IF($B$2="YoY","",IF(OR(Level_SA!OV11="",Level_SA!OW11="",Level_SA!OW11=0),"",Level_SA!OV11/Level_SA!OW11-1)) -> -0.036525974 | OW11: =IF($B$2="YoY","",IF(OR(Level_SA!OW11="",Level_SA!OX11="",Level_SA!OX11=0),"",Level_SA!OW11/Level_SA!OX11-1)) -> -0.0096463023 | OX11: =IF($B$2="YoY","",IF(OR(Level_SA!OX11="",Level_SA!OY11="",Level_SA!OY11=0),"",Level_SA!OX11/Level_SA!OY11-1)) -> 0.0032258065 | OY11: =IF($B$2="YoY","",IF(OR(Level_SA!OY11="",Level_SA!OZ11="",Level_SA!OZ11=0),"",Level_SA!OY11/Level_SA!OZ11-1)) -> 0.030114226 | ... PB11: =IF($B$2="YoY","",IF(OR(Level_SA!PB11="",Level_SA!PC11="",Level_SA!PC11=0),"",Level_SA!PB11/Level_SA!PC11-1)) | PC11: =IF($B$2="YoY","","")
A12: Aluminum and nonferrous metals | B12: AANMNO | C12: =IF($B$2="YoY",IF(OR(Level_SA!C12="",Level_SA!O12="",Level_SA!O12=0),"",Level_SA!C12/Level_SA!O12-1),IF(OR(Level_SA!C12="",Level_SA!D12="",Level_SA!D12=0),"",Level_SA!C12/Level_SA!D12-1)) | D12: =IF($B$2="YoY",IF(OR(Level_SA!D12="",Level_SA!P12="",Level_SA!P12=0),"",Level_SA!D12/Level_SA!P12-1),IF(OR(Level_SA!D12="",Level_SA!E12="",Level_SA!E12=0),"",Level_SA!D12/Level_SA!E12-1)) -> 0.017081851 | E12: =IF($B$2="YoY",IF(OR(Level_SA!E12="",Level_SA!Q12="",Level_SA!Q12=0),"",Level_SA!E12/Level_SA!Q12-1),IF(OR(Level_SA!E12="",Level_SA!F12="",Level_SA!F12=0),"",Level_SA!E12/Level_SA!F12-1)) -> 0.0078909613 | F12: =IF($B$2="YoY",IF(OR(Level_SA!F12="",Level_SA!R12="",Level_SA!R12=0),"",Level_SA!F12/Level_SA!R12-1),IF(OR(Level_SA!F12="",Level_SA!G12="",Level_SA!G12=0),"",Level_SA!F12/Level_SA!G12-1)) -> 0.0069020867 | G12: =IF($B$2="YoY",IF(OR(Level_SA!G12="",Level_SA!S12="",Level_SA!S12=0),"",Level_SA!G12/Level_SA!S12-1),IF(OR(Level_SA!G12="",Level_SA!H12="",Level_SA!H12=0),"",Level_SA!G12/Level_SA!H12-1)) -> 0.039459414 | H12: =IF($B$2="YoY",IF(OR(Level_SA!H12="",Level_SA!T12="",Level_SA!T12=0),"",Level_SA!H12/Level_SA!T12-1),IF(OR(Level_SA!H12="",Level_SA!I12="",Level_SA!I12=0),"",Level_SA!H12/Level_SA!I12-1)) -> 0.039275186 | I12: =IF($B$2="YoY",IF(OR(Level_SA!I12="",Level_SA!U12="",Level_SA!U12=0),"",Level_SA!I12/Level_SA!U12-1),IF(OR(Level_SA!I12="",Level_SA!J12="",Level_SA!J12=0),"",Level_SA!I12/Level_SA!J12-1)) -> -0.013429134 | J12: =IF($B$2="YoY",IF(OR(Level_SA!J12="",Level_SA!V12="",Level_SA!V12=0),"",Level_SA!J12/Level_SA!V12-1),IF(OR(Level_SA!J12="",Level_SA!K12="",Level_SA!K12=0),"",Level_SA!J12/Level_SA!K12-1)) -> 0.021672638 | ... OQ12: =IF($B$2="YoY",IF(OR(Level_SA!OQ12="",Level_SA!PC12="",Level_SA!PC12=0),"",Level_SA!OQ12/Level_SA!PC12-1),IF(OR(Level_SA!OQ12="",Level_SA!OR12="",Level_SA!OR12=0),"",Level_SA!OQ12/Level_SA!OR12-1)) -> 0.036201117 | OR12: =IF($B$2="YoY","",IF(OR(Level_SA!OR12="",Level_SA!OS12="",Level_SA!OS12=0),"",Level_SA!OR12/Level_SA!OS12-1)) -> -0.036805854 | OS12: =IF($B$2="YoY","",IF(OR(Level_SA!OS12="",Level_SA!OT12="",Level_SA!OT12=0),"",Level_SA!OS12/Level_SA!OT12-1)) -> 0.0097804825 | OT12: =IF($B$2="YoY","",IF(OR(Level_SA!OT12="",Level_SA!OU12="",Level_SA!OU12=0),"",Level_SA!OT12/Level_SA!OU12-1)) -> 0.022217285 | OU12: =IF($B$2="YoY","",IF(OR(Level_SA!OU12="",Level_SA!OV12="",Level_SA!OV12=0),"",Level_SA!OU12/Level_SA!OV12-1)) -> -0.081990618 | OV12: =IF($B$2="YoY","",IF(OR(Level_SA!OV12="",Level_SA!OW12="",Level_SA!OW12=0),"",Level_SA!OV12/Level_SA!OW12-1)) -> -0.012487412 | OW12: =IF($B$2="YoY","",IF(OR(Level_SA!OW12="",Level_SA!OX12="",Level_SA!OX12=0),"",Level_SA!OW12/Level_SA!OX12-1)) -> 0.030938538 | OX12: =IF($B$2="YoY","",IF(OR(Level_SA!OX12="",Level_SA!OY12="",Level_SA!OY12=0),"",Level_SA!OX12/Level_SA!OY12-1)) -> 0.010279001 | OY12: =IF($B$2="YoY","",IF(OR(Level_SA!OY12="",Level_SA!OZ12="",Level_SA!OZ12=0),"",Level_SA!OY12/Level_SA!OZ12-1)) -> 0.027149321 | ... PB12: =IF($B$2="YoY","",IF(OR(Level_SA!PB12="",Level_SA!PC12="",Level_SA!PC12=0),"",Level_SA!PB12/Level_SA!PC12-1)) | PC12: =IF($B$2="YoY","","")
A13: Ferrous metal foundries | B13: A31CNO | C13: =IF($B$2="YoY",IF(OR(Level_SA!C13="",Level_SA!O13="",Level_SA!O13=0),"",Level_SA!C13/Level_SA!O13-1),IF(OR(Level_SA!C13="",Level_SA!D13="",Level_SA!D13=0),"",Level_SA!C13/Level_SA!D13-1)) | D13: =IF($B$2="YoY",IF(OR(Level_SA!D13="",Level_SA!P13="",Level_SA!P13=0),"",Level_SA!D13/Level_SA!P13-1),IF(OR(Level_SA!D13="",Level_SA!E13="",Level_SA!E13=0),"",Level_SA!D13/Level_SA!E13-1)) -> 0.003968254 | E13: =IF($B$2="YoY",IF(OR(Level_SA!E13="",Level_SA!Q13="",Level_SA!Q13=0),"",Level_SA!E13/Level_SA!Q13-1),IF(OR(Level_SA!E13="",Level_SA!F13="",Level_SA!F13=0),"",Level_SA!E13/Level_SA!F13-1)) -> 0.028105168 | F13: =IF($B$2="YoY",IF(OR(Level_SA!F13="",Level_SA!R13="",Level_SA!R13=0),"",Level_SA!F13/Level_SA!R13-1),IF(OR(Level_SA!F13="",Level_SA!G13="",Level_SA!G13=0),"",Level_SA!F13/Level_SA!G13-1)) -> 0.017997231 | G13: =IF($B$2="YoY",IF(OR(Level_SA!G13="",Level_SA!S13="",Level_SA!S13=0),"",Level_SA!G13/Level_SA!S13-1),IF(OR(Level_SA!G13="",Level_SA!H13="",Level_SA!H13=0),"",Level_SA!G13/Level_SA!H13-1)) -> 0.0680138 | H13: =IF($B$2="YoY",IF(OR(Level_SA!H13="",Level_SA!T13="",Level_SA!T13=0),"",Level_SA!H13/Level_SA!T13-1),IF(OR(Level_SA!H13="",Level_SA!I13="",Level_SA!I13=0),"",Level_SA!H13/Level_SA!I13-1)) -> 0.027341772 | I13: =IF($B$2="YoY",IF(OR(Level_SA!I13="",Level_SA!U13="",Level_SA!U13=0),"",Level_SA!I13/Level_SA!U13-1),IF(OR(Level_SA!I13="",Level_SA!J13="",Level_SA!J13=0),"",Level_SA!I13/Level_SA!J13-1)) -> -0.027093596 | J13: =IF($B$2="YoY",IF(OR(Level_SA!J13="",Level_SA!V13="",Level_SA!V13=0),"",Level_SA!J13/Level_SA!V13-1),IF(OR(Level_SA!J13="",Level_SA!K13="",Level_SA!K13=0),"",Level_SA!J13/Level_SA!K13-1)) -> 0.044238683 | ... OQ13: =IF($B$2="YoY",IF(OR(Level_SA!OQ13="",Level_SA!PC13="",Level_SA!PC13=0),"",Level_SA!OQ13/Level_SA!PC13-1),IF(OR(Level_SA!OQ13="",Level_SA!OR13="",Level_SA!OR13=0),"",Level_SA!OQ13/Level_SA!OR13-1)) -> 0.01314459 | OR13: =IF($B$2="YoY","",IF(OR(Level_SA!OR13="",Level_SA!OS13="",Level_SA!OS13=0),"",Level_SA!OR13/Level_SA!OS13-1)) -> -0.05177373 | OS13: =IF($B$2="YoY","",IF(OR(Level_SA!OS13="",Level_SA!OT13="",Level_SA!OT13=0),"",Level_SA!OS13/Level_SA!OT13-1)) -> 0.077479339 | OT13: =IF($B$2="YoY","",IF(OR(Level_SA!OT13="",Level_SA!OU13="",Level_SA!OU13=0),"",Level_SA!OT13/Level_SA!OU13-1)) -> 0.071982281 | OU13: =IF($B$2="YoY","",IF(OR(Level_SA!OU13="",Level_SA!OV13="",Level_SA!OV13=0),"",Level_SA!OU13/Level_SA!OV13-1)) -> -0.19875776 | OV13: =IF($B$2="YoY","",IF(OR(Level_SA!OV13="",Level_SA!OW13="",Level_SA!OW13=0),"",Level_SA!OV13/Level_SA!OW13-1)) -> 0.24118943 | OW13: =IF($B$2="YoY","",IF(OR(Level_SA!OW13="",Level_SA!OX13="",Level_SA!OX13=0),"",Level_SA!OW13/Level_SA!OX13-1)) -> -0.1184466 | OX13: =IF($B$2="YoY","",IF(OR(Level_SA!OX13="",Level_SA!OY13="",Level_SA!OY13=0),"",Level_SA!OX13/Level_SA!OY13-1)) -> -0.020912548 | OY13: =IF($B$2="YoY","",IF(OR(Level_SA!OY13="",Level_SA!OZ13="",Level_SA!OZ13=0),"",Level_SA!OY13/Level_SA!OZ13-1)) -> 0.0562249 | ... PB13: =IF($B$2="YoY","",IF(OR(Level_SA!PB13="",Level_SA!PC13="",Level_SA!PC13=0),"",Level_SA!PB13/Level_SA!PC13-1)) | PC13: =IF($B$2="YoY","","")
A14: Fabricated metal products | B14: A32SNO | C14: =IF($B$2="YoY",IF(OR(Level_SA!C14="",Level_SA!O14="",Level_SA!O14=0),"",Level_SA!C14/Level_SA!O14-1),IF(OR(Level_SA!C14="",Level_SA!D14="",Level_SA!D14=0),"",Level_SA!C14/Level_SA!D14-1)) -> 0.003711771 | D14: =IF($B$2="YoY",IF(OR(Level_SA!D14="",Level_SA!P14="",Level_SA!P14=0),"",Level_SA!D14/Level_SA!P14-1),IF(OR(Level_SA!D14="",Level_SA!E14="",Level_SA!E14=0),"",Level_SA!D14/Level_SA!E14-1)) -> -0.013528032 | E14: =IF($B$2="YoY",IF(OR(Level_SA!E14="",Level_SA!Q14="",Level_SA!Q14=0),"",Level_SA!E14/Level_SA!Q14-1),IF(OR(Level_SA!E14="",Level_SA!F14="",Level_SA!F14=0),"",Level_SA!E14/Level_SA!F14-1)) -> 0.0041611625 | F14: =IF($B$2="YoY",IF(OR(Level_SA!F14="",Level_SA!R14="",Level_SA!R14=0),"",Level_SA!F14/Level_SA!R14-1),IF(OR(Level_SA!F14="",Level_SA!G14="",Level_SA!G14=0),"",Level_SA!F14/Level_SA!G14-1)) -> -0.0009677987 | G14: =IF($B$2="YoY",IF(OR(Level_SA!G14="",Level_SA!S14="",Level_SA!S14=0),"",Level_SA!G14/Level_SA!S14-1),IF(OR(Level_SA!G14="",Level_SA!H14="",Level_SA!H14=0),"",Level_SA!G14/Level_SA!H14-1)) -> 0.014323323 | H14: =IF($B$2="YoY",IF(OR(Level_SA!H14="",Level_SA!T14="",Level_SA!T14=0),"",Level_SA!H14/Level_SA!T14-1),IF(OR(Level_SA!H14="",Level_SA!I14="",Level_SA!I14=0),"",Level_SA!H14/Level_SA!I14-1)) -> 0.041766415 | I14: =IF($B$2="YoY",IF(OR(Level_SA!I14="",Level_SA!U14="",Level_SA!U14=0),"",Level_SA!I14/Level_SA!U14-1),IF(OR(Level_SA!I14="",Level_SA!J14="",Level_SA!J14=0),"",Level_SA!I14/Level_SA!J14-1)) -> -0.000116198 | J14: =IF($B$2="YoY",IF(OR(Level_SA!J14="",Level_SA!V14="",Level_SA!V14=0),"",Level_SA!J14/Level_SA!V14-1),IF(OR(Level_SA!J14="",Level_SA!K14="",Level_SA!K14=0),"",Level_SA!J14/Level_SA!K14-1)) -> 0.010924468 | ... OQ14: =IF($B$2="YoY",IF(OR(Level_SA!OQ14="",Level_SA!PC14="",Level_SA!PC14=0),"",Level_SA!OQ14/Level_SA!PC14-1),IF(OR(Level_SA!OQ14="",Level_SA!OR14="",Level_SA!OR14=0),"",Level_SA!OQ14/Level_SA!OR14-1)) -> -0.06821529 | OR14: =IF($B$2="YoY","",IF(OR(Level_SA!OR14="",Level_SA!OS14="",Level_SA!OS14=0),"",Level_SA!OR14/Level_SA!OS14-1)) -> 0.04454234 | OS14: =IF($B$2="YoY","",IF(OR(Level_SA!OS14="",Level_SA!OT14="",Level_SA!OT14=0),"",Level_SA!OS14/Level_SA!OT14-1)) -> -0.016505055 | OT14: =IF($B$2="YoY","",IF(OR(Level_SA!OT14="",Level_SA!OU14="",Level_SA!OU14=0),"",Level_SA!OT14/Level_SA!OU14-1)) -> -0.0013049451 | OU14: =IF($B$2="YoY","",IF(OR(Level_SA!OU14="",Level_SA!OV14="",Level_SA!OV14=0),"",Level_SA!OU14/Level_SA!OV14-1)) -> 0.028539135 | OV14: =IF($B$2="YoY","",IF(OR(Level_SA!OV14="",Level_SA!OW14="",Level_SA!OW14=0),"",Level_SA!OV14/Level_SA!OW14-1)) -> 0.011793296 | OW14: =IF($B$2="YoY","",IF(OR(Level_SA!OW14="",Level_SA!OX14="",Level_SA!OX14=0),"",Level_SA!OW14/Level_SA!OX14-1)) -> -0.029481132 | OX14: =IF($B$2="YoY","",IF(OR(Level_SA!OX14="",Level_SA!OY14="",Level_SA!OY14=0),"",Level_SA!OX14/Level_SA!OY14-1)) -> 0.023427517 | OY14: =IF($B$2="YoY","",IF(OR(Level_SA!OY14="",Level_SA!OZ14="",Level_SA!OZ14=0),"",Level_SA!OY14/Level_SA!OZ14-1)) -> 0.047987501 | ... PB14: =IF($B$2="YoY","",IF(OR(Level_SA!PB14="",Level_SA!PC14="",Level_SA!PC14=0),"",Level_SA!PB14/Level_SA!PC14-1)) | PC14: =IF($B$2="YoY","","")
A15: Machinery | B15: A33SNO | C15: =IF($B$2="YoY",IF(OR(Level_SA!C15="",Level_SA!O15="",Level_SA!O15=0),"",Level_SA!C15/Level_SA!O15-1),IF(OR(Level_SA!C15="",Level_SA!D15="",Level_SA!D15=0),"",Level_SA!C15/Level_SA!D15-1)) -> 0.011750985 | D15: =IF($B$2="YoY",IF(OR(Level_SA!D15="",Level_SA!P15="",Level_SA!P15=0),"",Level_SA!D15/Level_SA!P15-1),IF(OR(Level_SA!D15="",Level_SA!E15="",Level_SA!E15=0),"",Level_SA!D15/Level_SA!E15-1)) -> 0.010293464 | E15: =IF($B$2="YoY",IF(OR(Level_SA!E15="",Level_SA!Q15="",Level_SA!Q15=0),"",Level_SA!E15/Level_SA!Q15-1),IF(OR(Level_SA!E15="",Level_SA!F15="",Level_SA!F15=0),"",Level_SA!E15/Level_SA!F15-1)) -> 0.015189473 | F15: =IF($B$2="YoY",IF(OR(Level_SA!F15="",Level_SA!R15="",Level_SA!R15=0),"",Level_SA!F15/Level_SA!R15-1),IF(OR(Level_SA!F15="",Level_SA!G15="",Level_SA!G15=0),"",Level_SA!F15/Level_SA!G15-1)) -> 0.012962963 | G15: =IF($B$2="YoY",IF(OR(Level_SA!G15="",Level_SA!S15="",Level_SA!S15=0),"",Level_SA!G15/Level_SA!S15-1),IF(OR(Level_SA!G15="",Level_SA!H15="",Level_SA!H15=0),"",Level_SA!G15/Level_SA!H15-1)) -> 0.028789162 | H15: =IF($B$2="YoY",IF(OR(Level_SA!H15="",Level_SA!T15="",Level_SA!T15=0),"",Level_SA!H15/Level_SA!T15-1),IF(OR(Level_SA!H15="",Level_SA!I15="",Level_SA!I15=0),"",Level_SA!H15/Level_SA!I15-1)) -> 0.013178276 | I15: =IF($B$2="YoY",IF(OR(Level_SA!I15="",Level_SA!U15="",Level_SA!U15=0),"",Level_SA!I15/Level_SA!U15-1),IF(OR(Level_SA!I15="",Level_SA!J15="",Level_SA!J15=0),"",Level_SA!I15/Level_SA!J15-1)) -> 0.01230309 | J15: =IF($B$2="YoY",IF(OR(Level_SA!J15="",Level_SA!V15="",Level_SA!V15=0),"",Level_SA!J15/Level_SA!V15-1),IF(OR(Level_SA!J15="",Level_SA!K15="",Level_SA!K15=0),"",Level_SA!J15/Level_SA!K15-1)) -> 0.023505592 | ... OQ15: =IF($B$2="YoY",IF(OR(Level_SA!OQ15="",Level_SA!PC15="",Level_SA!PC15=0),"",Level_SA!OQ15/Level_SA!PC15-1),IF(OR(Level_SA!OQ15="",Level_SA!OR15="",Level_SA!OR15=0),"",Level_SA!OQ15/Level_SA!OR15-1)) -> -0.025023946 | OR15: =IF($B$2="YoY","",IF(OR(Level_SA!OR15="",Level_SA!OS15="",Level_SA!OS15=0),"",Level_SA!OR15/Level_SA!OS15-1)) -> 0.039387717 | OS15: =IF($B$2="YoY","",IF(OR(Level_SA!OS15="",Level_SA!OT15="",Level_SA!OT15=0),"",Level_SA!OS15/Level_SA!OT15-1)) -> 0.028214971 | OT15: =IF($B$2="YoY","",IF(OR(Level_SA!OT15="",Level_SA!OU15="",Level_SA!OU15=0),"",Level_SA!OT15/Level_SA!OU15-1)) -> -0.053358367 | OU15: =IF($B$2="YoY","",IF(OR(Level_SA!OU15="",Level_SA!OV15="",Level_SA!OV15=0),"",Level_SA!OU15/Level_SA!OV15-1)) -> 0.073606867 | OV15: =IF($B$2="YoY","",IF(OR(Level_SA!OV15="",Level_SA!OW15="",Level_SA!OW15=0),"",Level_SA!OV15/Level_SA!OW15-1)) -> -0.0051106223 | OW15: =IF($B$2="YoY","",IF(OR(Level_SA!OW15="",Level_SA!OX15="",Level_SA!OX15=0),"",Level_SA!OW15/Level_SA!OX15-1)) -> -0.035622933 | OX15: =IF($B$2="YoY","",IF(OR(Level_SA!OX15="",Level_SA!OY15="",Level_SA!OY15=0),"",Level_SA!OX15/Level_SA!OY15-1)) -> 0.03821491 | OY15: =IF($B$2="YoY","",IF(OR(Level_SA!OY15="",Level_SA!OZ15="",Level_SA!OZ15=0),"",Level_SA!OY15/Level_SA!OZ15-1)) -> -0.016874682 | ... PB15: =IF($B$2="YoY","",IF(OR(Level_SA!PB15="",Level_SA!PC15="",Level_SA!PC15=0),"",Level_SA!PB15/Level_SA!PC15-1)) | PC15: =IF($B$2="YoY","","")
A16: Construction machinery | B16: A33CNO | C16: =IF($B$2="YoY",IF(OR(Level_SA!C16="",Level_SA!O16="",Level_SA!O16=0),"",Level_SA!C16/Level_SA!O16-1),IF(OR(Level_SA!C16="",Level_SA!D16="",Level_SA!D16=0),"",Level_SA!C16/Level_SA!D16-1)) | D16: =IF($B$2="YoY",IF(OR(Level_SA!D16="",Level_SA!P16="",Level_SA!P16=0),"",Level_SA!D16/Level_SA!P16-1),IF(OR(Level_SA!D16="",Level_SA!E16="",Level_SA!E16=0),"",Level_SA!D16/Level_SA!E16-1)) -> 0.072466866 | E16: =IF($B$2="YoY",IF(OR(Level_SA!E16="",Level_SA!Q16="",Level_SA!Q16=0),"",Level_SA!E16/Level_SA!Q16-1),IF(OR(Level_SA!E16="",Level_SA!F16="",Level_SA!F16=0),"",Level_SA!E16/Level_SA!F16-1)) -> -0.086149639 | F16: =IF($B$2="YoY",IF(OR(Level_SA!F16="",Level_SA!R16="",Level_SA!R16=0),"",Level_SA!F16/Level_SA!R16-1),IF(OR(Level_SA!F16="",Level_SA!G16="",Level_SA!G16=0),"",Level_SA!F16/Level_SA!G16-1)) -> 0.021145023 | G16: =IF($B$2="YoY",IF(OR(Level_SA!G16="",Level_SA!S16="",Level_SA!S16=0),"",Level_SA!G16/Level_SA!S16-1),IF(OR(Level_SA!G16="",Level_SA!H16="",Level_SA!H16=0),"",Level_SA!G16/Level_SA!H16-1)) -> 0.058935361 | H16: =IF($B$2="YoY",IF(OR(Level_SA!H16="",Level_SA!T16="",Level_SA!T16=0),"",Level_SA!H16/Level_SA!T16-1),IF(OR(Level_SA!H16="",Level_SA!I16="",Level_SA!I16=0),"",Level_SA!H16/Level_SA!I16-1)) -> -0.0012658228 | I16: =IF($B$2="YoY",IF(OR(Level_SA!I16="",Level_SA!U16="",Level_SA!U16=0),"",Level_SA!I16/Level_SA!U16-1),IF(OR(Level_SA!I16="",Level_SA!J16="",Level_SA!J16=0),"",Level_SA!I16/Level_SA!J16-1)) -> 0.036745407 | J16: =IF($B$2="YoY",IF(OR(Level_SA!J16="",Level_SA!V16="",Level_SA!V16=0),"",Level_SA!J16/Level_SA!V16-1),IF(OR(Level_SA!J16="",Level_SA!K16="",Level_SA!K16=0),"",Level_SA!J16/Level_SA!K16-1)) -> 0.115394 | ... OQ16: =IF($B$2="YoY",IF(OR(Level_SA!OQ16="",Level_SA!PC16="",Level_SA!PC16=0),"",Level_SA!OQ16/Level_SA!PC16-1),IF(OR(Level_SA!OQ16="",Level_SA!OR16="",Level_SA!OR16=0),"",Level_SA!OQ16/Level_SA!OR16-1)) -> 0.075329567 | OR16: =IF($B$2="YoY","",IF(OR(Level_SA!OR16="",Level_SA!OS16="",Level_SA!OS16=0),"",Level_SA!OR16/Level_SA!OS16-1)) -> 0.051485149 | OS16: =IF($B$2="YoY","",IF(OR(Level_SA!OS16="",Level_SA!OT16="",Level_SA!OT16=0),"",Level_SA!OS16/Level_SA!OT16-1)) -> -0.29469274 | OT16: =IF($B$2="YoY","",IF(OR(Level_SA!OT16="",Level_SA!OU16="",Level_SA!OU16=0),"",Level_SA!OT16/Level_SA!OU16-1)) -> 0.080754717 | OU16: =IF($B$2="YoY","",IF(OR(Level_SA!OU16="",Level_SA!OV16="",Level_SA!OV16=0),"",Level_SA!OU16/Level_SA!OV16-1)) -> 0.39767932 | OV16: =IF($B$2="YoY","",IF(OR(Level_SA!OV16="",Level_SA!OW16="",Level_SA!OW16=0),"",Level_SA!OV16/Level_SA!OW16-1)) -> -0.069676153 | OW16: =IF($B$2="YoY","",IF(OR(Level_SA!OW16="",Level_SA!OX16="",Level_SA!OX16=0),"",Level_SA!OW16/Level_SA!OX16-1)) -> -0.038679245 | OX16: =IF($B$2="YoY","",IF(OR(Level_SA!OX16="",Level_SA!OY16="",Level_SA!OY16=0),"",Level_SA!OX16/Level_SA!OY16-1)) -> -0.051029543 | OY16: =IF($B$2="YoY","",IF(OR(Level_SA!OY16="",Level_SA!OZ16="",Level_SA!OZ16=0),"",Level_SA!OY16/Level_SA!OZ16-1)) -> 0.30034924 | ... PB16: =IF($B$2="YoY","",IF(OR(Level_SA!PB16="",Level_SA!PC16="",Level_SA!PC16=0),"",Level_SA!PB16/Level_SA!PC16-1)) | PC16: =IF($B$2="YoY","","")
... A42: Nondurable goods industries | B42: AMNMNO | C42: =IF($B$2="YoY",IF(OR(Level_SA!C42="",Level_SA!O42="",Level_SA!O42=0),"",Level_SA!C42/Level_SA!O42-1),IF(OR(Level_SA!C42="",Level_SA!D42="",Level_SA!D42=0),"",Level_SA!C42/Level_SA!D42-1)) | D42: =IF($B$2="YoY",IF(OR(Level_SA!D42="",Level_SA!P42="",Level_SA!P42=0),"",Level_SA!D42/Level_SA!P42-1),IF(OR(Level_SA!D42="",Level_SA!E42="",Level_SA!E42=0),"",Level_SA!D42/Level_SA!E42-1)) -> 0.0027642633 | E42: =IF($B$2="YoY",IF(OR(Level_SA!E42="",Level_SA!Q42="",Level_SA!Q42=0),"",Level_SA!E42/Level_SA!Q42-1),IF(OR(Level_SA!E42="",Level_SA!F42="",Level_SA!F42=0),"",Level_SA!E42/Level_SA!F42-1)) -> 0.0066022589 | F42: =IF($B$2="YoY",IF(OR(Level_SA!F42="",Level_SA!R42="",Level_SA!R42=0),"",Level_SA!F42/Level_SA!R42-1),IF(OR(Level_SA!F42="",Level_SA!G42="",Level_SA!G42=0),"",Level_SA!F42/Level_SA!G42-1)) -> -0.009178631 | G42: =IF($B$2="YoY",IF(OR(Level_SA!G42="",Level_SA!S42="",Level_SA!S42=0),"",Level_SA!G42/Level_SA!S42-1),IF(OR(Level_SA!G42="",Level_SA!H42="",Level_SA!H42=0),"",Level_SA!G42/Level_SA!H42-1)) -> 0.021582508 | H42: =IF($B$2="YoY",IF(OR(Level_SA!H42="",Level_SA!T42="",Level_SA!T42=0),"",Level_SA!H42/Level_SA!T42-1),IF(OR(Level_SA!H42="",Level_SA!I42="",Level_SA!I42=0),"",Level_SA!H42/Level_SA!I42-1)) -> 0.019102077 | I42: =IF($B$2="YoY",IF(OR(Level_SA!I42="",Level_SA!U42="",Level_SA!U42=0),"",Level_SA!I42/Level_SA!U42-1),IF(OR(Level_SA!I42="",Level_SA!J42="",Level_SA!J42=0),"",Level_SA!I42/Level_SA!J42-1)) -> 0.023253603 | J42: =IF($B$2="YoY",IF(OR(Level_SA!J42="",Level_SA!V42="",Level_SA!V42=0),"",Level_SA!J42/Level_SA!V42-1),IF(OR(Level_SA!J42="",Level_SA!K42="",Level_SA!K42=0),"",Level_SA!J42/Level_SA!K42-1)) -> 0.019019497 | ... OQ42: =IF($B$2="YoY",IF(OR(Level_SA!OQ42="",Level_SA!PC42="",Level_SA!PC42=0),"",Level_SA!OQ42/Level_SA!PC42-1),IF(OR(Level_SA!OQ42="",Level_SA!OR42="",Level_SA!OR42=0),"",Level_SA!OQ42/Level_SA!OR42-1)) -> 0.0016427731 | OR42: =IF($B$2="YoY","",IF(OR(Level_SA!OR42="",Level_SA!OS42="",Level_SA!OS42=0),"",Level_SA!OR42/Level_SA!OS42-1)) -> 0.0015350431 | OS42: =IF($B$2="YoY","",IF(OR(Level_SA!OS42="",Level_SA!OT42="",Level_SA!OT42=0),"",Level_SA!OS42/Level_SA!OT42-1)) -> 0.021670378 | OT42: =IF($B$2="YoY","",IF(OR(Level_SA!OT42="",Level_SA!OU42="",Level_SA!OU42=0),"",Level_SA!OT42/Level_SA!OU42-1)) -> -0.024758959 | OU42: =IF($B$2="YoY","",IF(OR(Level_SA!OU42="",Level_SA!OV42="",Level_SA!OV42=0),"",Level_SA!OU42/Level_SA!OV42-1)) -> 0.027069483 | OV42: =IF($B$2="YoY","",IF(OR(Level_SA!OV42="",Level_SA!OW42="",Level_SA!OW42=0),"",Level_SA!OV42/Level_SA!OW42-1)) -> -0.0068695645 | OW42: =IF($B$2="YoY","",IF(OR(Level_SA!OW42="",Level_SA!OX42="",Level_SA!OX42=0),"",Level_SA!OW42/Level_SA!OX42-1)) -> -0.015336174 | OX42: =IF($B$2="YoY","",IF(OR(Level_SA!OX42="",Level_SA!OY42="",Level_SA!OY42=0),"",Level_SA!OX42/Level_SA!OY42-1)) -> 0.014918945 | OY42: =IF($B$2="YoY","",IF(OR(Level_SA!OY42="",Level_SA!OZ42="",Level_SA!OZ42=0),"",Level_SA!OY42/Level_SA!OZ42-1)) -> 0.021028469 | ... PB42: =IF($B$2="YoY","",IF(OR(Level_SA!PB42="",Level_SA!PC42="",Level_SA!PC42=0),"",Level_SA!PB42/Level_SA!PC42-1)) -> -0.0072702095 | PC42: =IF($B$2="YoY","","")

Sheet Level_SA
A1: Value of Manufacturers' New Orders - Seasonally Adjusted (Millions of Dollars)
A3: Source: FRED series/observations (U.S. Census Bureau M3), fred DB에서 생성. 값은 원자료(하드코딩).
A4: Industry | B4: Ticker (SA) | C4: 2026-09 | D4: 2026-08 | E4: 2026-07 | F4: 2026-06 | G4: 2026-05 | H4: 2026-04 | I4: 2026-03 | J4: 2026-02 | K4: 2026-01 | L4: 2025-12 | M4: 2025-11 | N4: 2025-10 | O4: 2025-09 | P4: 2025-08 | Q4: 2025-07 | R4: 2025-06 | S4: 2025-05 | T4: 2025-04 | U4: 2025-03 | V4: 2025-02 | W4: 2025-01 | X4: 2024-12 | Y4: 2024-11 | Z4: 2024-10 | AA4: 2024-09 | AB4: 2024-08 | AC4: 2024-07 | AD4: 2024-06 | AE4: 2024-05 | AF4: 2024-04 | AG4: 2024-03 | AH4: 2024-02 | AI4: 2024-01 | AJ4: 2023-12 | AK4: 2023-11 | AL4: 2023-10 | AM4: 2023-09 | AN4: 2023-08 | AO4: 2023-07 | AP4: 2023-06 | AQ4: 2023-05 | AR4: 2023-04 | AS4: 2023-03 | AT4: 2023-02 | AU4: 2023-01 | AV4: 2022-12 | AW4: 2022-11 | AX4: 2022-10 | AY4: 2022-09 | AZ4: 2022-08 | BA4: 2022-07 | BB4: 2022-06 | BC4: 2022-05 | BD4: 2022-04 | BE4: 2022-03 | BF4: 2022-02 | BG4: 2022-01 | BH4: 2021-12 | BI4: 2021-11 | BJ4: 2021-10 | BK4: 2021-09 | BL4: 2021-08 | BM4: 2021-07 | BN4: 2021-06 | BO4: 2021-05 | BP4: 2021-04 | BQ4: 2021-03 | BR4: 2021-02 | BS4: 2021-01 | BT4: 2020-12 | BU4: 2020-11 | BV4: 2020-10 | BW4: 2020-09 | BX4: 2020-08 | BY4: 2020-07 | BZ4: 2020-06 | CA4: 2020-05 | CB4: 2020-04 | CC4: 2020-03 | CD4: 2020-02 | CE4: 2020-01 | CF4: 2019-12 | CG4: 2019-11 | CH4: 2019-10 | CI4: 2019-09 | CJ4: 2019-08 | CK4: 2019-07 | CL4: 2019-06 | CM4: 2019-05 | CN4: 2019-04 | CO4: 2019-03 | CP4: 2019-02 | CQ4: 2019-01 | CR4: 2018-12 | CS4: 2018-11 | CT4: 2018-10 | CU4: 2018-09 | CV4: 2018-08 | CW4: 2018-07 | CX4: 2018-06 | CY4: 2018-05 | CZ4: 2018-04 | DA4: 2018-03 | DB4: 2018-02 | DC4: 2018-01 | DD4: 2017-12 | DE4: 2017-11 | DF4: 2017-10 | DG4: 2017-09 | DH4: 2017-08 | DI4: 2017-07 | DJ4: 2017-06 | DK4: 2017-05 | DL4: 2017-04 | DM4: 2017-03 | DN4: 2017-02 | DO4: 2017-01 | DP4: 2016-12 | DQ4: 2016-11 | DR4: 2016-10 | DS4: 2016-09 | DT4: 2016-08 | DU4: 2016-07 | DV4: 2016-06 | DW4: 2016-05 | DX4: 2016-04 | DY4: 2016-03 | DZ4: 2016-02 | EA4: 2016-01 | EB4: 2015-12 | EC4: 2015-11 | ED4: 2015-10 | EE4: 2015-09 | EF4: 2015-08 | EG4: 2015-07 | EH4: 2015-06 | EI4: 2015-05 | EJ4: 2015-04 | EK4: 2015-03 | EL4: 2015-02 | EM4: 2015-01 | EN4: 2014-12 | EO4: 2014-11 | EP4: 2014-10 | EQ4: 2014-09 | ER4: 2014-08 | ES4: 2014-07 | ET4: 2014-06 | EU4: 2014-05 | EV4: 2014-04 | EW4: 2014-03 | EX4: 2014-02 | EY4: 2014-01 | EZ4: 2013-12 | FA4: 2013-11 | FB4: 2013-10 | FC4: 2013-09 | FD4: 2013-08 | FE4: 2013-07 | FF4: 2013-06 | FG4: 2013-05 | FH4: 2013-04 | FI4: 2013-03 | FJ4: 2013-02 | FK4: 2013-01 | FL4: 2012-12 | FM4: 2012-11 | FN4: 2012-10 | FO4: 2012-09 | FP4: 2012-08 | FQ4: 2012-07 | FR4: 2012-06 | FS4: 2012-05 | FT4: 2012-04 | FU4: 2012-03 | FV4: 2012-02 | FW4: 2012-01 | FX4: 2011-12 | FY4: 2011-11 | FZ4: 2011-10 | GA4: 2011-09 | GB4: 2011-08 | GC4: 2011-07 | GD4: 2011-06 | GE4: 2011-05 | GF4: 2011-04 | GG4: 2011-03 | GH4: 2011-02 | GI4: 2011-01 | GJ4: 2010-12 | GK4: 2010-11 | GL4: 2010-10 | GM4: 2010-09 | GN4: 2010-08 | GO4: 2010-07 | GP4: 2010-06 | GQ4: 2010-05 | GR4: 2010-04 | GS4: 2010-03 | GT4: 2010-02 | GU4: 2010-01 | GV4: 2009-12 | GW4: 2009-11 | GX4: 2009-10 | GY4: 2009-09 | GZ4: 2009-08 | HA4: 2009-07 | HB4: 2009-06 | HC4: 2009-05 | HD4: 2009-04 | HE4: 2009-03 | HF4: 2009-02 | HG4: 2009-01 | HH4: 2008-12 | HI4: 2008-11 | HJ4: 2008-10 | HK4: 2008-09 | HL4: 2008-08 | HM4: 2008-07 | HN4: 2008-06 | HO4: 2008-05 | HP4: 2008-04 | HQ4: 2008-03 | HR4: 2008-02 | HS4: 2008-01 | HT4: 2007-12 | HU4: 2007-11 | HV4: 2007-10 | HW4: 2007-09 | HX4: 2007-08 | HY4: 2007-07 | HZ4: 2007-06 | IA4: 2007-05 | IB4: 2007-04 | IC4: 2007-03 | ID4: 2007-02 | IE4: 2007-01 | IF4: 2006-12 | IG4: 2006-11 | IH4: 2006-10 | II4: 2006-09 | IJ4: 2006-08 | IK4: 2006-07 | IL4: 2006-06 | IM4: 2006-05 | IN4: 2006-04 | IO4: 2006-03 | IP4: 2006-02 | IQ4: 2006-01 | IR4: 2005-12 | IS4: 2005-11 | IT4: 2005-10 | IU4: 2005-09 | IV4: 2005-08 | IW4: 2005-07 | IX4: 2005-06 | IY4: 2005-05 | IZ4: 2005-04 | JA4: 2005-03 | JB4: 2005-02 | JC4: 2005-01 | JD4: 2004-12 | JE4: 2004-11 | JF4: 2004-10 | JG4: 2004-09 | JH4: 2004-08 | JI4: 2004-07 | JJ4: 2004-06 | JK4: 2004-05 | JL4: 2004-04 | JM4: 2004-03 | JN4: 2004-02 | JO4: 2004-01 | JP4: 2003-12 | JQ4: 2003-11 | JR4: 2003-10 | JS4: 2003-09 | JT4: 2003-08 | JU4: 2003-07 | JV4: 2003-06 | JW4: 2003-05 | JX4: 2003-04 | JY4: 2003-03 | JZ4: 2003-02 | KA4: 2003-01 | KB4: 2002-12 | KC4: 2002-11 | KD4: 2002-10 | KE4: 2002-09 | KF4: 2002-08 | KG4: 2002-07 | KH4: 2002-06 | KI4: 2002-05 | KJ4: 2002-04 | KK4: 2002-03 | KL4: 2002-02 | KM4: 2002-01 | KN4: 2001-12 | KO4: 2001-11 | KP4: 2001-10 | KQ4: 2001-09 | KR4: 2001-08 | KS4: 2001-07 | KT4: 2001-06 | KU4: 2001-05 | KV4: 2001-04 | KW4: 2001-03 | KX4: 2001-02 | KY4: 2001-01 | KZ4: 2000-12 | LA4: 2000-11 | LB4: 2000-10 | LC4: 2000-09 | LD4: 2000-08 | LE4: 2000-07 | LF4: 2000-06 | LG4: 2000-05 | LH4: 2000-04 | LI4: 2000-03 | LJ4: 2000-02 | LK4: 2000-01 | LL4: 1999-12 | LM4: 1999-11 | LN4: 1999-10 | LO4: 1999-09 | LP4: 1999-08 | LQ4: 1999-07 | LR4: 1999-06 | LS4: 1999-05 | LT4: 1999-04 | LU4: 1999-03 | LV4: 1999-02 | LW4: 1999-01 | LX4: 1998-12 | LY4: 1998-11 | LZ4: 1998-10 | MA4: 1998-09 | MB4: 1998-08 | MC4: 1998-07 | MD4: 1998-06 | ME4: 1998-05 | MF4: 1998-04 | MG4: 1998-03 | MH4: 1998-02 | MI4: 1998-01 | MJ4: 1997-12 | MK4: 1997-11 | ML4: 1997-10 | MM4: 1997-09 | MN4: 1997-08 | MO4: 1997-07 | MP4: 1997-06 | MQ4: 1997-05 | MR4: 1997-04 | MS4: 1997-03 | MT4: 1997-02 | MU4: 1997-01 | MV4: 1996-12 | MW4: 1996-11 | MX4: 1996-10 | MY4: 1996-09 | MZ4: 1996-08 | NA4: 1996-07 | NB4: 1996-06 | NC4: 1996-05 | ND4: 1996-04 | NE4: 1996-03 | NF4: 1996-02 | NG4: 1996-01 | NH4: 1995-12 | NI4: 1995-11 | NJ4: 1995-10 | NK4: 1995-09 | NL4: 1995-08 | NM4: 1995-07 | NN4: 1995-06 | NO4: 1995-05 | NP4: 1995-04 | NQ4: 1995-03 | NR4: 1995-02 | NS4: 1995-01 | NT4: 1994-12 | NU4: 1994-11 | NV4: 1994-10 | NW4: 1994-09 | NX4: 1994-08 | NY4: 1994-07 | NZ4: 1994-06 | OA4: 1994-05 | OB4: 1994-04 | OC4: 1994-03 | OD4: 1994-02 | OE4: 1994-01 | OF4: 1993-12 | OG4: 1993-11 | OH4: 1993-10 | OI4: 1993-09 | OJ4: 1993-08 | OK4: 1993-07 | OL4: 1993-06 | OM4: 1993-05 | ON4: 1993-04 | OO4: 1993-03 | OP4: 1993-02 | OQ4: 1993-01 | OR4: 1992-12 | OS4: 1992-11 | OT4: 1992-10 | OU4: 1992-09 | OV4: 1992-08 | OW4: 1992-07 | OX4: 1992-06 | OY4: 1992-05 | OZ4: 1992-04 | PA4: 1992-03 | PB4: 1992-02 | PC4: 1992-01
